<?xml version="1.0" encoding="utf-8"?>
<!-- =================================================================================== -->
<!-- |    This document was autogenerated by xacro from xarm_device.urdf.xacro         | -->
<!-- |    EDITING THIS FILE BY HAND IS NOT RECOMMENDED                                 | -->
<!-- =================================================================================== -->
<robot name="floating_xarm">
  <!-- Insert at the beginning of xarm_device_macro.xacro -->
  <material name="Black">
    <color rgba="0.0 0.0 0.0 1.0"/>
  </material>
  <material name="Red">
    <color rgba="0.8 0.0 0.0 1.0"/>
  </material>
  <material name="White">
    <color rgba="1.0 1.0 1.0 1.0"/>
  </material>
  <material name="Silver">
    <color rgba="0.753 0.753 0.753 1.0"/>
  </material>
  <link name="root"/>
  <link name="root1"/>
  <link name="root2"/>
  <link name="root3"/>
  <link name="root4"/>
  <link name="root5"/>
  <link name="root6"/>
  <joint name="x_axis_joint" type="prismatic">
    <parent link="root"/>
    <child link="root1"/>
    <axis xyz="1 0 0"/>
    <limit effort="50" lower="-10" upper="10" velocity="0.50"/>
    <dynamics damping="10.0" friction="10"/>
  </joint>
  <joint name="y_axis_joint" type="prismatic">
    <parent link="root1"/>
    <child link="root2"/>
    <axis xyz="0 1 0"/>
    <limit effort="50" lower="-10" upper="10" velocity="0.50"/>
    <dynamics damping="10.0" friction="10"/>
  </joint>
  <joint name="z_axis_joint" type="prismatic">
    <parent link="root2"/>
    <child link="root3"/>
    <axis xyz="0 0 1"/>
    <limit effort="50" lower="-10" upper="10" velocity="0.50"/>
    <dynamics damping="10.0" friction="10"/>
  </joint>
  <joint name="x_rotation_joint" type="continuous">
    <parent link="root3"/>
    <child link="root4"/>
    <axis xyz="1 0 0"/>
    <dynamics damping="10.0" friction="1"/>
  </joint>
  <joint name="y_rotation_joint" type="continuous">
    <parent link="root4"/>
    <child link="root5"/>
    <axis xyz="0 1 0"/>
    <dynamics damping="10.0" friction="1"/>
  </joint>
  <joint name="z_rotation_joint" type="continuous">
    <parent link="root5"/>
    <child link="root6"/>
    <axis xyz="0 0 1"/>
    <dynamics damping="10.0" friction="1"/>
  </joint>
  <link name="link_eef">
    <visual>
      <geometry>
        <mesh filename="xarm_description/meshes/camera/realsense/visual/d435_with_tilt_cam_stand.STL"/>
      </geometry>
      <origin rpy="0 0 3.141592653589793" xyz="0 0 0"/>
      <material name="Silver"/>
    </visual>
    <collision>
      <geometry>
        <mesh filename="xarm_description/meshes/camera/realsense/collision/d435_with_tilt_cam_stand.STL"/>
      </geometry>
      <origin rpy="0 0 3.141592653589793" xyz="0 0 0"/>
    </collision>
  </link>
  <link name="camera_link"/>
  <link name="camera_depth_frame"/>
  <link name="camera_depth_optical_frame"/>
  <link name="camera_color_frame"/>
  <link name="camera_color_optical_frame"/>
  <link name="camera_left_ir_frame"/>
  <link name="camera_left_ir_optical_frame"/>
  <link name="camera_right_ir_frame"/>
  <link name="camera_right_ir_optical_frame"/>
  <!-- Compute origin xyz
    x, z = 0.06746, 0.0237
    r = np.sqrt(x**2 + z**2)
    dx, dz = 0.0014, -0.0112  # from blender model
    theta = np.arctan2(z, x)
    new_x = r * np.cos(theta + np.deg2rad(15)) + dx
    new_z = r * np.sin(theta + np.deg2rad(15)) + dz
  -->
  <joint name="camera_link_joint" type="fixed">
    <parent link="link_eef"/>
    <child link="camera_link"/>
    <origin rpy="3.141592653589793 -1.832595714594046 3.141592653589793" xyz="-0.06042734 0.0175 0.02915237"/>
  </joint>
  <joint name="camera_depth_joint" type="fixed">
    <parent link="camera_link"/>
    <child link="camera_depth_frame"/>
    <origin rpy="0 0 0" xyz="0 0 0"/>
  </joint>
  <joint name="camera_depth_optical_joint" type="fixed">
    <parent link="camera_depth_frame"/>
    <child link="camera_depth_optical_frame"/>
    <origin rpy="-1.5707963267948966 0 -1.5707963267948966" xyz="0 0 0"/>
  </joint>
  <joint name="camera_color_joint" type="fixed">
    <parent link="camera_link"/>
    <child link="camera_color_frame"/>
    <origin rpy="0 0 0" xyz="0 0.015 0"/>
  </joint>
  <joint name="camera_color_optical_joint" type="fixed">
    <parent link="camera_color_frame"/>
    <child link="camera_color_optical_frame"/>
    <origin rpy="-1.5707963267948966 0 -1.5707963267948966" xyz="0 0 0"/>
  </joint>
  <joint name="camera_left_ir_joint" type="fixed">
    <parent link="camera_link"/>
    <child link="camera_left_ir_frame"/>
    <origin rpy="0 0 0" xyz="0 0 0"/>
  </joint>
  <joint name="camera_left_ir_optical_joint" type="fixed">
    <parent link="camera_left_ir_frame"/>
    <child link="camera_left_ir_optical_frame"/>
    <origin rpy="-1.5707963267948966 0 -1.5707963267948966" xyz="0 0 0"/>
  </joint>
  <joint name="camera_right_ir_joint" type="fixed">
    <parent link="camera_link"/>
    <child link="camera_right_ir_frame"/>
    <origin rpy="0 0 0" xyz="0 -0.050 0"/>
  </joint>
  <joint name="camera_right_ir_optical_joint" type="fixed">
    <parent link="camera_right_ir_frame"/>
    <child link="camera_right_ir_optical_frame"/>
    <origin rpy="-1.5707963267948966 0 -1.5707963267948966" xyz="0 0 0"/>
  </joint>
  <joint name="joint_eef" type="fixed">
    <origin rpy="0 0 0" xyz="0 0 -0.005"/>
    <parent link="root6"/>
    <child link="link_eef"/>
  </joint>
  <joint name="gripper_fix" type="fixed">
    <parent link="link_eef"/>
    <child link="xarm_gripper_base_link"/>
    <origin rpy="0 0 0" xyz="0 0 0.005"/>
  </joint>
  <link name="xarm_gripper_base_link">
    <inertial>
      <origin rpy="0 0 0" xyz="-0.00065489 -0.0018497 0.048028"/>
      <mass value="0.54156"/>
      <inertia ixx="0.00047106" ixy="3.9292E-07" ixz="2.6537E-06" iyy="0.00033072" iyz="-1.0975E-05" izz="0.00025642"/>
    </inertial>
    <visual>
      <geometry>
        <mesh filename="xarm_description/meshes/gripper/xarm/base_link.STL"/>
      </geometry>
      <origin rpy="0 0 0" xyz="0 0 0"/>
      <material name="White"/>
    </visual>
    <collision>
      <geometry>
        <mesh filename="xarm_description/meshes/gripper/xarm/base_link_collision.STL"/>
      </geometry>
      <origin rpy="0 0 0" xyz="0 0 0"/>
    </collision>
  </link>
  <link name="left_finger">
    <inertial>
      <origin rpy="0 0 0" xyz="-2.4536E-14 -0.016413 0.029258"/>
      <mass value="0.048304"/>
      <inertia ixx="1.7493E-05" ixy="-4.2156E-19" ixz="6.9164E-18" iyy="1.7225E-05" iyz="4.6433E-06" izz="5.1466E-06"/>
    </inertial>
    <visual>
      <geometry>
        <mesh filename="xarm_description/meshes/gripper/xarm/left_finger_black.glb"/>
      </geometry>
      <origin rpy="0 0 0" xyz="0 0 0"/>
      <material name="Silver"/>
    </visual>
    <collision>
      <geometry>
        <mesh filename="xarm_description/meshes/gripper/xarm/left_finger_black.glb"/>
      </geometry>
      <origin rpy="0 0 0" xyz="0 0 0"/>
    </collision>
  </link>
  <joint name="left_finger_joint" type="prismatic">
    <origin rpy="0 0 0" xyz="0 0.02682323 0.11348719"/>
    <parent link="xarm_gripper_base_link"/>
    <child link="left_finger"/>
    <axis xyz="0 0.96221329 -0.27229686"/>
    <limit effort="50" lower="0" upper="0.0453556139430441" velocity="0.5"/>
  </joint>
  <link name="right_finger">
    <inertial>
      <origin rpy="0 0 0" xyz="2.5618E-14 0.016413 0.029258"/>
      <mass value="0.048304"/>
      <inertia ixx="1.7493E-05" ixy="-5.0014E-19" ixz="-7.5079E-18" iyy="1.7225E-05" iyz="-4.6435E-06" izz="5.1466E-06"/>
    </inertial>
    <visual>
      <geometry>
        <mesh filename="xarm_description/meshes/gripper/xarm/right_finger_black.glb"/>
      </geometry>
      <origin rpy="0 0 0" xyz="0 0 0"/>
      <material name="Silver"/>
    </visual>
    <collision>
      <geometry>
        <mesh filename="xarm_description/meshes/gripper/xarm/right_finger_black.glb"/>
      </geometry>
      <origin rpy="0 0 0" xyz="0 0 0"/>
    </collision>
  </link>
  <joint name="right_finger_joint" type="prismatic">
    <origin rpy="0 0 0" xyz="0 -0.02682323 0.11348719"/>
    <parent link="xarm_gripper_base_link"/>
    <child link="right_finger"/>
    <axis xyz="0. -0.96221329 -0.27229686"/>
    <limit effort="50" lower="0" upper="0.0453556139430441" velocity="0.5"/>
  </joint>
  <link name="link_tcp"/>
  <joint name="joint_tcp" type="fixed">
    <origin rpy="0 0 0" xyz="0 0 0.172"/>
    <parent link="xarm_gripper_base_link"/>
    <child link="link_tcp"/>
  </joint>
  <!-- Insert at the end of xarm_device_macro.xacro -->
</robot>
